<?xml version="1.0" ?>
<!-- =================================================================================== -->
<!-- |    This document was autogenerated by xacro from ../x001_description/urdf/x001.urdf.xacro | -->
<!-- |    EDITING THIS FILE BY HAND IS NOT RECOMMENDED                                 | -->
<!-- =================================================================================== -->
<robot name="x001">
  <material name="white">
    <color rgba="1 1 1 1"/>
  </material>
  <material name="black">
    <color rgba="0 0 0 1"/>
  </material>
  <material name="blue">
    <color rgba="0 0 1 1"/>
  </material>
  <material name="green">
    <color rgba="0 1 0 1"/>
  </material>
  <material name="grey">
    <color rgba="0.5 0.5 0.5 1"/>
  </material>
  <material name="orange">
    <color rgba="1 0.5 0 1"/>
  </material>
  <material name="brown">
    <color rgba="0.87 0.72 0.53 1"/>
  </material>
  <material name="purple">
    <color rgba="0.5 0 0.5 1"/>
  </material>
  <material name="red">
    <color rgba="1 0 0 1"/>
  </material>
  <!-- BASE LINKS -->
  <link name="base_footprint"/>
  <link name="base_link">
    <visual>
      <geometry>
        <box size="0.6 0.3 0.15"/>
      </geometry>
      <material name="green"/>
      <origin rpy="0.0 0.0 0.0" xyz="0 0 0"/>
    </visual>
    <collision>
      <geometry>
        <box size="0.6 0.3 0.15"/>
      </geometry>
    </collision>
    <inertial>
      <mass value="1.0"/>
      <inertia ixx="0.031875" ixy="0.0" ixz="0.0" iyy="0.009374999999999998" iyz="0.0" izz="0.03749999999999999"/>
    </inertial>
  </link>
  <joint name="base_footprint_to_link" type="fixed">
    <parent link="base_footprint"/>
    <child link="base_link"/>
    <origin rpy="0.0 0.0 0.0" xyz="0 0.0 0.075"/>
  </joint>
  <link name="left_wheel">
    <visual>
      <geometry>
        <cylinder length="0.04" radius="0.1"/>
      </geometry>
      <origin rpy="1.5707963267948966 0.0 0.0" xyz="0.0 0.0 0.0"/>
    </visual>
    <collision>
      <geometry>
        <cylinder length="0.04" radius="0.1"/>
      </geometry>
      <origin rpy="0.0 0.0 0.0" xyz="0.0 0.0 0.0"/>
    </collision>
    <inertial>
      <mass value="0.1"/>
      <inertia ixx="0.00026333333333333336" ixy="0.0" ixz="0.0" iyy="0.00026333333333333336" iyz="0.0" izz="0.0005000000000000001"/>
    </inertial>
  </link>
  <joint name="base_link_to_left_wheel" type="continuous">
    <parent link="base_link"/>
    <child link="left_wheel"/>
    <axis xyz="0.0 1 0.0"/>
    <origin rpy="0.0 0.0 0.0" xyz="-0.15 -0.16999999999999998 -0.075"/>
  </joint>
  <link name="right_wheel">
    <visual>
      <geometry>
        <cylinder length="0.04" radius="0.1"/>
      </geometry>
      <origin rpy="1.5707963267948966 0.0 0.0" xyz="0.0 0.0 0.0"/>
    </visual>
    <collision>
      <geometry>
        <cylinder length="0.04" radius="0.1"/>
      </geometry>
      <origin rpy="0.0 0.0 0.0" xyz="0.0 0.0 0.0"/>
    </collision>
    <inertial>
      <mass value="0.1"/>
      <inertia ixx="0.00026333333333333336" ixy="0.0" ixz="0.0" iyy="0.00026333333333333336" iyz="0.0" izz="0.0005000000000000001"/>
    </inertial>
  </link>
  <joint name="base_link_to_right_wheel" type="continuous">
    <parent link="base_link"/>
    <child link="right_wheel"/>
    <axis xyz="0.0 1 0.0"/>
    <origin rpy="0.0 0.0 0.0" xyz="-0.15 +0.16999999999999998 -0.075"/>
  </joint>
  <!-- CASTER -->
  <link name="caster_wheel">
    <visual>
      <geometry>
        <sphere radius="0.03"/>
      </geometry>
      <material name="black"/>
      <origin rpy="0.0 0.0 0.0" xyz="0.0 0.0 0.0"/>
    </visual>
    <collision>
      <geometry>
        <sphere radius="0.03"/>
      </geometry>
      <origin rpy="0.0 0.0 0.0" xyz="0.0 0.0 0.0"/>
    </collision>
    <mass value="2"/>
    <inertia ixx="0.0011999999999999997" ixy="0.0" ixz="0.0" iyy="0.0011999999999999997" iyz="0.0" izz="0.0011999999999999997"/>
  </link>
  <joint name="base_link_to_caster_wheel" type="fixed">
    <parent link="base_link"/>
    <child link="caster_wheel"/>
    <origin rpy="0.0 0.0 0.0" xyz="0.15 0.0 -0.105"/>
  </joint>
</robot>
